Workbook

Sheet Project
I8: CAPSTONE PROJECT
I10: Financial Statement Analysis

Sheet Executive Summary

Sheet Introduction

Sheet Company_Profile

Sheet Industry & Business Model

Sheet Past Financials>>>

Sheet Income Statement
A2: Consolidated Income Statement
B4: Particulars (₹ in Crores) | C4: 2020 | D4: =C4+1 -> 2021 | E4: =D4+1 -> 2022 | F4: =E4+1 -> 2023 | G4: =F4+1 -> 2024 | H4: =G4+1 -> 2025
B5: Revenue From Operations | C5: =20025.96+ 22.36+ 162.93 -> 20211.25 | D5: =21440.24+44.96+227.59 -> 21712.79 | E5: =28830.02 +93.46 +177.8 -> 29101.28 | F5: =34253.35 +114.48 +120.76 -> 34488.59 | G5: =35248.88+133.24+112.61 -> 35494.73 | H5: =33626.82+170.54+108.26 -> 33905.62
B6: Other Income | C6: 304.31 | D6: 303.05 | E6: 380.01 | F6: 386.48 | G6: 687.96 | H6: 572.61
B7: Total Income | C7: =SUM(C5:C6) -> 20515.56 | D7: =SUM(D5:D6) -> 22015.84 | E7: =SUM(E5:E6) -> 29481.29 | F7: =SUM(F5:F6) -> 34875.07 | G7: =SUM(G5:G6) -> 36182.69 | H7: =SUM(H5:H6) -> 34478.23
B9: Expenses
B10: Cost of Materials Consumed | C10: 10091.78 | D10: 10317.09 | E10: 16254.59 | F10: 17330.58 | G10: 15868.21 | H10: 15793.92
B11: Purchases of Stock-in-Trade | C11: 1530.83 | D11: 1872.59 | E11: 3371.13 | F11: 4135.65 | G11: 3858.2 | H11: 3926.86
B12: Changes in inventories | C12: -239.15 | D12: -92.45 | E12: -1324.97 | F12: -309.73 | G12: 363.8 | H12: -205
B13: Employee Benefits Expense | C13: 1366.09 | D13: 1540.75 | E13: 1786.67 | F13: 2028.07 | G13: 2326.18 | H13: 2597.23
B14: Other Expenses | C14: 3299.93 | D14: 3219.21 | E14: 4210.25 | F14: 5044.18 | G14: 5493.36 | H14: 5786.4
B15: Total Expenses | C15: =SUM(C10:C14) -> 16049.48 | D15: =SUM(D10:D14) -> 16857.19 | E15: =SUM(E10:E14) -> 24297.67 | F15: =SUM(F10:F14) -> 28228.75 | G15: =SUM(G10:G14) -> 27909.75 | H15: =SUM(H10:H14) -> 27899.41
B17: EBITDA | C17: =C7-C15 -> 4466.08 | D17: =D7-D15 -> 5158.65 | E17: =E7-E15 -> 5183.62 | F17: =F7-F15 -> 6646.32 | G17: =G7-G15 -> 8272.94 | H17: =H7-H15 -> 6578.82
B18: Depreciation and Amortisation Expense | C18: 780.5 | D18: 791.27 | E18: 816.36 | F18: 858.02 | G18: 853 | H18: 1026.34
B19: EBIT | C19: =C17-C18 -> 3685.58 | D19: =D17-D18 -> 4367.38 | E19: =E17-E18 -> 4367.26 | F19: =F17-F18 -> 5788.3 | G19: =G17-G18 -> 7419.94 | H19: =H17-H18 -> 5552.48
B20: Finance Costs | C20: 102.33 | D20: 91.63 | E20: 95.41 | F20: 144.45 | G20: 205.17 | H20: 227.02
B21: =PROPER("PROFIT BEFORE SHARE OF PROFIT IN ASSOCIATES AND EXCEPTIONAL ITEMS") -> Profit Before Share Of Profit In Associates And Exceptional Items | C21: =C19-C20 -> 3583.25 | D21: =D19-D20 -> 4275.75 | E21: =E19-E20 -> 4271.85 | F21: =F19-F20 -> 5643.85 | G21: =G19-G20 -> 7214.77 | H21: =H19-H20 -> 5325.46
B22: Share of profit in Associates | C22: 50.74 | D22: 28.6 | E22: 31.57 | F22: 93.85 | G22: 133 | H22: 140.71
B23: Profit Before Exceptional Items And Tax | C23: =C21+C22 -> 3633.99 | D23: =D21+D22 -> 4304.35 | E23: =E21+E22 -> 4303.42 | F23: =F21+F22 -> 5737.7 | G23: =G21+G22 -> 7347.77 | H23: =H21+H22 -> 5466.17
B24: Exceptional Items | C24: 0 | D24: 0 | E24: 115.7 | F24: 48.87 | G24: 0 | H24: 363.1
B25: EBT | C25: =C23-C24 -> 3633.99 | D25: =D23-D24 -> 4304.35 | E25: =E23-E24 -> 4187.72 | F25: =F23-F24 -> 5688.83 | G25: =G23-G24 -> 7347.77 | H25: =H23-H24 -> 5103.07
B26: Tax expense | C26: 854.85 | D26: 1097.6 | E26: 1102.91 | F26: 1493.5 | G26: 1790.08 | H26: 1393.36
B27: PAT | C27: =C25-C26 -> 2779.14 | D27: =D25-D26 -> 3206.75 | E27: =E25-E26 -> 3084.81 | F27: =F25-F26 -> 4195.33 | G27: =G25-G26 -> 5557.69 | H27: =H25-H26 -> 3709.71

Sheet Balance Sheet
A2: Consolidated Balance Sheet
B4: ='Income Statement'!B4 -> Particulars (₹ in Crores) | C4: ='Income Statement'!C4 -> 2020 | D4: ='Income Statement'!D4 -> 2021 | E4: ='Income Statement'!E4 -> 2022 | F4: ='Income Statement'!F4 -> 2023 | G4: ='Income Statement'!G4 -> 2024 | H4: ='Income Statement'!H4 -> 2025
B5: Equity & Liabilities
B6: Equity
B7: Equity Share Capital | C7: 95.92 | D7: 95.92 | E7: 95.92 | F7: 95.92 | G7: 95.92 | H7: 95.92
B8: Other Equity | C8: 10034.24 | D8: 12710.37 | E8: 13715.64 | F8: 15896.31 | G8: 18632.38 | H8: 19303.89
B9: Equity attributable to owners | C9: =SUM(C7:C8) -> 10130.16 | D9: =SUM(D7:D8) -> 12806.29 | E9: =SUM(E7:E8) -> 13811.56 | F9: =SUM(F7:F8) -> 15992.23 | G9: =SUM(G7:G8) -> 18728.3 | H9: =SUM(H7:H8) -> 19399.81
B10: Non-Controlling Interests | C10: 403.53 | D10: 422.86 | E10: 387.53 | F10: 453.66 | G10: 695.38 | H10: 659.24
B11: Total Equity | C11: =SUM(C9+C10) -> 10533.69 | D11: =SUM(D9+D10) -> 13229.15 | E11: =SUM(E9+E10) -> 14199.09 | F11: =SUM(F9+F10) -> 16445.89 | G11: =SUM(G9+G10) -> 19423.68 | H11: =SUM(H9+H10) -> 20059.05
B13: Liabilities
B14: Non-Current Liabilities
B15: Long Term Borrowings | C15: =18.63+ 589.94 -> 608.57 | D15: =14.53+ 561.36 -> 575.89 | E15: =44.54+ 598.37 -> 642.91 | F15: =76.15+ 728.94 -> 805.09 | G15: =54.38+ 1095.29 -> 1149.67 | H15: =259.62+ 1123.3 -> 1382.92
B16: Other Non-Current Liabilities | C16: =2.94+ 180.75+ 443.8+ 4.64 -> 632.13 | D16: =3.38+ 215.21+ 415.59+ 4.54 -> 638.72 | E16: =2.18+ 218.32+ 348.85+ 2.11 -> 571.46 | F16: =46.38+ 230.7+ 334.84+ 39.17 -> 651.09 | G16: =240.58+ 222.56+ 352.17+ 34.47 -> 849.78 | H16: =79.93+ 257.78+ 404.91+ 45.55 -> 788.17
B17: Total Non-Current Liabilities | C17: =SUM(C15:C16) -> 1240.7 | D17: =SUM(D15:D16) -> 1214.61 | E17: =SUM(E15:E16) -> 1214.37 | F17: =SUM(F15:F16) -> 1456.18 | G17: =SUM(G15:G16) -> 1999.45 | H17: =SUM(H15:H16) -> 2171.09
B19: Current Liabilities
B20: Short Term Borrowings | C20: =321.48+ 173.87 -> 495.35 | D20: =334.05+ 183.18 -> 517.23 | E20: =731.12+ 212.85 -> 943.97 | F20: =896.06+ 231.47 -> 1127.53 | G20: =1052.76+ 271.95 -> 1324.71 | H20: =604.13+ 303.24 -> 907.37
B21: Trade Payables | C21: =60.72+ 2075.85 -> 2136.57 | D21: =91.53+ 3287.19 -> 3378.72 | E21: =83.58+ 4080.72 -> 4164.3 | F21: =143.88+ 3491.56 -> 3635.44 | G21: =250.27+ 3581.07 -> 3831.34 | H21: =208.58+ 3639.42 -> 3848
B22: Other Current Liabilities | C22: =1374.34+ 131.61+ 62.46+ 180.05 -> 1748.46 | D22: =1594.67+ 229.58+ 84.43+ 121.23 -> 2029.91 | E22: =1886.81+ 376.09+ 69.7+ 130.12 -> 2462.72 | F22: =2436.02+ 459.04+ 74.21+ 163.69 -> 3132.96 | G22: =2675.44+ 484.48+ 62.48+ 122.51 -> 3344.91 | H22: =2742.04+ 450.58+ 67.15+ 126.09 -> 3385.86
B23: Total Current Liabilities | C23: =SUM(C20:C22) -> 4380.38 | D23: =SUM(D20:D22) -> 5925.86 | E23: =SUM(E20:E22) -> 7570.99 | F23: =SUM(F20:F22) -> 7895.93 | G23: =SUM(G20:G22) -> 8500.96 | H23: =SUM(H20:H22) -> 8141.23
B24: TOTAL EQUITIES & LIABILITIES | C24: =C11+C17+C23 -> 16154.77 | D24: =D11+D17+D23 -> 20369.62 | E24: =E11+E17+E23 -> 22984.45 | F24: =F11+F17+F23 -> 25798 | G24: =G11+G17+G23 -> 29924.09 | H24: =H11+H17+H23 -> 30371.37
B26: Assets
B27: Total Non-Current Assets | C27: 8574.66 | D27: 8343.02 | E27: 7832.12 | F27: 9262.84 | G27: 12387.03 | H27: 13379.69
B29: Current Assets
B30: Inventories | C30: 3389.81 | D30: 3798.6 | E30: 6152.98 | F30: 6210.64 | G30: 5923.41 | H30: 6719.27
B31: Trade Receivables | C31: 1795.22 | D31: 2602.17 | E31: 3871.44 | F31: 4636.94 | G31: 4889.05 | H31: 4313.65
B32: Cash, Bank & Cash Equivalents | C32: =563.83+ 219 -> 782.83 | D32: =346.39+ 264.36 -> 610.75 | E32: =621.72+ 242.61 -> 864.33 | F32: =523.1+ 320.72 -> 843.82 | G32: =829.34+254.67 -> 1084.01 | H32: =445.28+336.7 -> 781.98
B33: Other Current Assets | C33: =512.48+18.67+ 781.65+ 285.59+ 13.86 -> 1612.25 | D33: =3267.12+1197.24+537.23+13.49 -> 5015.08 | E33: =2180.7+1533.5+ 541.25+ 8.13 -> 4263.58 | F33: =2697+1592.78+ 553.98 -> 4843.76 | G33: =3203.41+1651.35+ 785.83 -> 5640.59 | H33: =3244.96+1158.11+773.71 -> 5176.78
B34: Total Current Assets | C34: =SUM(C30:C33) -> 7580.11 | D34: =SUM(D30:D33) -> 12026.6 | E34: =SUM(E30:E33) -> 15152.33 | F34: =SUM(F30:F33) -> 16535.16 | G34: =SUM(G30:G33) -> 17537.06 | H34: =SUM(H30:H33) -> 16991.68
B35: TOTAL ASSETS | C35: =C27+C34 -> 16154.77 | D35: =D27+D34 -> 20369.62 | E35: =E27+E34 -> 22984.45 | F35: =F27+F34 -> 25798 | G35: =G27+G34 -> 29924.09 | H35: =H27+H34 -> 30371.37
B37: Check | C37: =ROUND(C35-C24,0) -> 0 | D37: =ROUND(D35-D24,0) -> 0 | E37: =ROUND(E35-E24,0) -> 0 | F37: =ROUND(F35-F24,0) -> 0 | G37: =ROUND(G35-G24,0) -> 0 | H37: =ROUND(H35-H24,0) -> 0
B39: No. of shares (in cr) | C39: 95.919779 | D39: 95.919779 | E39: 95.919779 | F39: 95.919779 | G39: 95.919779 | H39: 95.919779
B40: Total Debt | C40: =+C15+C20 -> 1103.92 | D40: =+D15+D20 -> 1093.12 | E40: =+E15+E20 -> 1586.88 | F40: =+F15+F20 -> 1932.62 | G40: =+G15+G20 -> 2474.38 | H40: =+H15+H20 -> 2290.29
B41: Net Debt | C41: =C40-C32 -> 321.09 | D41: =D40-D32 -> 482.37 | E41: =E40-E32 -> 722.55 | F41: =F40-F32 -> 1088.8 | G41: =G40-G32 -> 1390.37 | H41: =H40-H32 -> 1508.31

Sheet Analysis>>>

Sheet CFS_Analysis
A2: Consolidated Statement of Cash Flows
B4: ='Income Statement'!B4 -> Particulars (₹ in Crores) | C4: ='Income Statement'!D4 -> 2021 | D4: ='Income Statement'!E4 -> 2022 | E4: ='Income Statement'!F4 -> 2023 | F4: ='Income Statement'!G4 -> 2024 | G4: ='Income Statement'!H4 -> 2025
B5: Cash Flow from Operating Activities (CFO) | C5: 3683 | D5: 986 | E5: 4193 | F5: 6103 | G5: 4423
B6: Cash Flow from Investing Activities (CFI) | C6: -547 | D6: -321 | E6: -1274 | F6: -2517 | G6: -874
B7: Cash Flow from Financing Activities (CFF) | C7: -650 | D7: -1807 | E7: -2140 | F7: -2982 | G7: -3752
B8: Net Change in Cash | C8: =SUM(C5:C7) -> 2486 | D8: =SUM(D5:D7) -> -1142 | E8: =SUM(E5:E7) -> 779 | F8: =SUM(F5:F7) -> 604 | G8: =SUM(G5:G7) -> -203

Sheet Common Size_IS
C1: =MATCH(C4,'Income Statement'!$4:$4,0) -> 3 | D1: =MATCH(D4,'Income Statement'!$4:$4,0) -> 4 | E1: =MATCH(E4,'Income Statement'!$4:$4,0) -> 5 | F1: =MATCH(F4,'Income Statement'!$4:$4,0) -> 6 | G1: =MATCH(G4,'Income Statement'!$4:$4,0) -> 7 | H1: =MATCH(H4,'Income Statement'!$4:$4,0) -> 8
A2: Common-Size Income Statement (with Revenue from Operations as base)
B4: Particulars | C4: ='Income Statement'!C4 -> 2020 | D4: ='Income Statement'!D4 -> 2021 | E4: ='Income Statement'!E4 -> 2022 | F4: ='Income Statement'!F4 -> 2023 | G4: ='Income Statement'!G4 -> 2024 | H4: ='Income Statement'!H4 -> 2025
A5: =MATCH($B5,'Income Statement'!$B:$B,0) -> 5 | B5: Revenue From Operations | C5: {=INDEX('Income Statement'!$A$1:$H$27,'Common Size_IS'!$A5,'Common Size_IS'!C$1)/INDEX('Income Statement'!$A$1:$H$27,'Common Size_IS'!$A$5,'Common Size_IS'!C$1)} -> 1 | D5: {=INDEX('Income Statement'!$A$1:$H$27,'Common Size_IS'!$A5,'Common Size_IS'!D$1)/INDEX('Income Statement'!$A$1:$H$27,'Common Size_IS'!$A$5,'Common Size_IS'!D$1)} -> 1 | E5: {=INDEX('Income Statement'!$A$1:$H$27,'Common Size_IS'!$A5,'Common Size_IS'!E$1)/INDEX('Income Statement'!$A$1:$H$27,'Common Size_IS'!$A$5,'Common Size_IS'!E$1)} -> 1 | F5: {=INDEX('Income Statement'!$A$1:$H$27,'Common Size_IS'!$A5,'Common Size_IS'!F$1)/INDEX('Income Statement'!$A$1:$H$27,'Common Size_IS'!$A$5,'Common Size_IS'!F$1)} -> 1 | G5: {=INDEX('Income Statement'!$A$1:$H$27,'Common Size_IS'!$A5,'Common Size_IS'!G$1)/INDEX('Income Statement'!$A$1:$H$27,'Common Size_IS'!$A$5,'Common Size_IS'!G$1)} -> 1 | H5: {=INDEX('Income Statement'!$A$1:$H$27,'Common Size_IS'!$A5,'Common Size_IS'!H$1)/INDEX('Income Statement'!$A$1:$H$27,'Common Size_IS'!$A$5,'Common Size_IS'!H$1)} -> 1
A6: =MATCH($B6,'Income Statement'!$B:$B,0) -> 6 | B6: Other Income | C6: {=INDEX('Income Statement'!$A$1:$H$27,'Common Size_IS'!$A6,'Common Size_IS'!C$1)/INDEX('Income Statement'!$A$1:$H$27,'Common Size_IS'!$A$5,'Common Size_IS'!C$1)} -> 0.015056466 | D6: {=INDEX('Income Statement'!$A$1:$H$27,'Common Size_IS'!$A6,'Common Size_IS'!D$1)/INDEX('Income Statement'!$A$1:$H$27,'Common Size_IS'!$A$5,'Common Size_IS'!D$1)} -> 0.013957211 | E6: {=INDEX('Income Statement'!$A$1:$H$27,'Common Size_IS'!$A6,'Common Size_IS'!E$1)/INDEX('Income Statement'!$A$1:$H$27,'Common Size_IS'!$A$5,'Common Size_IS'!E$1)} -> 0.013058189 | F6: {=INDEX('Income Statement'!$A$1:$H$27,'Common Size_IS'!$A6,'Common Size_IS'!F$1)/INDEX('Income Statement'!$A$1:$H$27,'Common Size_IS'!$A$5,'Common Size_IS'!F$1)} -> 0.011206025 | G6: {=INDEX('Income Statement'!$A$1:$H$27,'Common Size_IS'!$A6,'Common Size_IS'!G$1)/INDEX('Income Statement'!$A$1:$H$27,'Common Size_IS'!$A$5,'Common Size_IS'!G$1)} -> 0.019382032 | H6: {=INDEX('Income Statement'!$A$1:$H$27,'Common Size_IS'!$A6,'Common Size_IS'!H$1)/INDEX('Income Statement'!$A$1:$H$27,'Common Size_IS'!$A$5,'Common Size_IS'!H$1)} -> 0.016888351
A7: =MATCH($B7,'Income Statement'!$B:$B,0) -> 7 | B7: Total Income | C7: {=INDEX('Income Statement'!$A$1:$H$27,'Common Size_IS'!$A7,'Common Size_IS'!C$1)/INDEX('Income Statement'!$A$1:$H$27,'Common Size_IS'!$A$5,'Common Size_IS'!C$1)} -> 1.0150565 | D7: {=INDEX('Income Statement'!$A$1:$H$27,'Common Size_IS'!$A7,'Common Size_IS'!D$1)/INDEX('Income Statement'!$A$1:$H$27,'Common Size_IS'!$A$5,'Common Size_IS'!D$1)} -> 1.0139572 | E7: {=INDEX('Income Statement'!$A$1:$H$27,'Common Size_IS'!$A7,'Common Size_IS'!E$1)/INDEX('Income Statement'!$A$1:$H$27,'Common Size_IS'!$A$5,'Common Size_IS'!E$1)} -> 1.0130582 | F7: {=INDEX('Income Statement'!$A$1:$H$27,'Common Size_IS'!$A7,'Common Size_IS'!F$1)/INDEX('Income Statement'!$A$1:$H$27,'Common Size_IS'!$A$5,'Common Size_IS'!F$1)} -> 1.011206 | G7: {=INDEX('Income Statement'!$A$1:$H$27,'Common Size_IS'!$A7,'Common Size_IS'!G$1)/INDEX('Income Statement'!$A$1:$H$27,'Common Size_IS'!$A$5,'Common Size_IS'!G$1)} -> 1.019382 | H7: {=INDEX('Income Statement'!$A$1:$H$27,'Common Size_IS'!$A7,'Common Size_IS'!H$1)/INDEX('Income Statement'!$A$1:$H$27,'Common Size_IS'!$A$5,'Common Size_IS'!H$1)} -> 1.0168884
A9: =MATCH($B9,'Income Statement'!$B:$B,0) -> 9 | B9: Expenses | C9: {=INDEX('Income Statement'!$A$1:$H$27,'Common Size_IS'!$A9,'Common Size_IS'!C$1)/INDEX('Income Statement'!$A$1:$H$27,'Common Size_IS'!$A$5,'Common Size_IS'!C$1)} -> 0 | D9: {=INDEX('Income Statement'!$A$1:$H$27,'Common Size_IS'!$A9,'Common Size_IS'!D$1)/INDEX('Income Statement'!$A$1:$H$27,'Common Size_IS'!$A$5,'Common Size_IS'!D$1)} -> 0 | E9: {=INDEX('Income Statement'!$A$1:$H$27,'Common Size_IS'!$A9,'Common Size_IS'!E$1)/INDEX('Income Statement'!$A$1:$H$27,'Common Size_IS'!$A$5,'Common Size_IS'!E$1)} -> 0 | F9: {=INDEX('Income Statement'!$A$1:$H$27,'Common Size_IS'!$A9,'Common Size_IS'!F$1)/INDEX('Income Statement'!$A$1:$H$27,'Common Size_IS'!$A$5,'Common Size_IS'!F$1)} -> 0 | G9: {=INDEX('Income Statement'!$A$1:$H$27,'Common Size_IS'!$A9,'Common Size_IS'!G$1)/INDEX('Income Statement'!$A$1:$H$27,'Common Size_IS'!$A$5,'Common Size_IS'!G$1)} -> 0 | H9: {=INDEX('Income Statement'!$A$1:$H$27,'Common Size_IS'!$A9,'Common Size_IS'!H$1)/INDEX('Income Statement'!$A$1:$H$27,'Common Size_IS'!$A$5,'Common Size_IS'!H$1)} -> 0
A10: =MATCH($B10,'Income Statement'!$B:$B,0) -> 10 | B10: Cost of Materials Consumed | C10: {=INDEX('Income Statement'!$A$1:$H$27,'Common Size_IS'!$A10,'Common Size_IS'!C$1)/INDEX('Income Statement'!$A$1:$H$27,'Common Size_IS'!$A$5,'Common Size_IS'!C$1)} -> 0.49931499 | D10: {=INDEX('Income Statement'!$A$1:$H$27,'Common Size_IS'!$A10,'Common Size_IS'!D$1)/INDEX('Income Statement'!$A$1:$H$27,'Common Size_IS'!$A$5,'Common Size_IS'!D$1)} -> 0.47516187 | E10: {=INDEX('Income Statement'!$A$1:$H$27,'Common Size_IS'!$A10,'Common Size_IS'!E$1)/INDEX('Income Statement'!$A$1:$H$27,'Common Size_IS'!$A$5,'Common Size_IS'!E$1)} -> 0.55855241 | F10: {=INDEX('Income Statement'!$A$1:$H$27,'Common Size_IS'!$A10,'Common Size_IS'!F$1)/INDEX('Income Statement'!$A$1:$H$27,'Common Size_IS'!$A$5,'Common Size_IS'!F$1)} -> 0.50250184 | G10: {=INDEX('Income Statement'!$A$1:$H$27,'Common Size_IS'!$A10,'Common Size_IS'!G$1)/INDEX('Income Statement'!$A$1:$H$27,'Common Size_IS'!$A$5,'Common Size_IS'!G$1)} -> 0.4470582 | H10: {=INDEX('Income Statement'!$A$1:$H$27,'Common Size_IS'!$A10,'Common Size_IS'!H$1)/INDEX('Income Statement'!$A$1:$H$27,'Common Size_IS'!$A$5,'Common Size_IS'!H$1)} -> 0.46582012
A11: =MATCH($B11,'Income Statement'!$B:$B,0) -> 11 | B11: Purchases of Stock-in-Trade | C11: {=INDEX('Income Statement'!$A$1:$H$27,'Common Size_IS'!$A11,'Common Size_IS'!C$1)/INDEX('Income Statement'!$A$1:$H$27,'Common Size_IS'!$A$5,'Common Size_IS'!C$1)} -> 0.075741481 | D11: {=INDEX('Income Statement'!$A$1:$H$27,'Common Size_IS'!$A11,'Common Size_IS'!D$1)/INDEX('Income Statement'!$A$1:$H$27,'Common Size_IS'!$A$5,'Common Size_IS'!D$1)} -> 0.086243638 | E11: {=INDEX('Income Statement'!$A$1:$H$27,'Common Size_IS'!$A11,'Common Size_IS'!E$1)/INDEX('Income Statement'!$A$1:$H$27,'Common Size_IS'!$A$5,'Common Size_IS'!E$1)} -> 0.1158413 | F11: {=INDEX('Income Statement'!$A$1:$H$27,'Common Size_IS'!$A11,'Common Size_IS'!F$1)/INDEX('Income Statement'!$A$1:$H$27,'Common Size_IS'!$A$5,'Common Size_IS'!F$1)} -> 0.11991357 | G11: {=INDEX('Income Statement'!$A$1:$H$27,'Common Size_IS'!$A11,'Common Size_IS'!G$1)/INDEX('Income Statement'!$A$1:$H$27,'Common Size_IS'!$A$5,'Common Size_IS'!G$1)} -> 0.10869783 | H11: {=INDEX('Income Statement'!$A$1:$H$27,'Common Size_IS'!$A11,'Common Size_IS'!H$1)/INDEX('Income Statement'!$A$1:$H$27,'Common Size_IS'!$A$5,'Common Size_IS'!H$1)} -> 0.11581738
A12: =MATCH($B12,'Income Statement'!$B:$B,0) -> 12 | B12: Changes in inventories | C12: {=INDEX('Income Statement'!$A$1:$H$27,'Common Size_IS'!$A12,'Common Size_IS'!C$1)/INDEX('Income Statement'!$A$1:$H$27,'Common Size_IS'!$A$5,'Common Size_IS'!C$1)} -> -0.011832519 | D12: {=INDEX('Income Statement'!$A$1:$H$27,'Common Size_IS'!$A12,'Common Size_IS'!D$1)/INDEX('Income Statement'!$A$1:$H$27,'Common Size_IS'!$A$5,'Common Size_IS'!D$1)} -> -0.0042578591 | E12: {=INDEX('Income Statement'!$A$1:$H$27,'Common Size_IS'!$A12,'Common Size_IS'!E$1)/INDEX('Income Statement'!$A$1:$H$27,'Common Size_IS'!$A$5,'Common Size_IS'!E$1)} -> -0.045529612 | F12: {=INDEX('Income Statement'!$A$1:$H$27,'Common Size_IS'!$A12,'Common Size_IS'!F$1)/INDEX('Income Statement'!$A$1:$H$27,'Common Size_IS'!$A$5,'Common Size_IS'!F$1)} -> -0.0089806513 | G12: {=INDEX('Income Statement'!$A$1:$H$27,'Common Size_IS'!$A12,'Common Size_IS'!G$1)/INDEX('Income Statement'!$A$1:$H$27,'Common Size_IS'!$A$5,'Common Size_IS'!G$1)} -> 0.010249409 | H12: {=INDEX('Income Statement'!$A$1:$H$27,'Common Size_IS'!$A12,'Common Size_IS'!H$1)/INDEX('Income Statement'!$A$1:$H$27,'Common Size_IS'!$A$5,'Common Size_IS'!H$1)} -> -0.0060461953
A13: =MATCH($B13,'Income Statement'!$B:$B,0) -> 13 | B13: Employee Benefits Expense | C13: {=INDEX('Income Statement'!$A$1:$H$27,'Common Size_IS'!$A13,'Common Size_IS'!C$1)/INDEX('Income Statement'!$A$1:$H$27,'Common Size_IS'!$A$5,'Common Size_IS'!C$1)} -> 0.067590575 | D13: {=INDEX('Income Statement'!$A$1:$H$27,'Common Size_IS'!$A13,'Common Size_IS'!D$1)/INDEX('Income Statement'!$A$1:$H$27,'Common Size_IS'!$A$5,'Common Size_IS'!D$1)} -> 0.07096048 | E13: {=INDEX('Income Statement'!$A$1:$H$27,'Common Size_IS'!$A13,'Common Size_IS'!E$1)/INDEX('Income Statement'!$A$1:$H$27,'Common Size_IS'!$A$5,'Common Size_IS'!E$1)} -> 0.061394894 | F13: {=INDEX('Income Statement'!$A$1:$H$27,'Common Size_IS'!$A13,'Common Size_IS'!F$1)/INDEX('Income Statement'!$A$1:$H$27,'Common Size_IS'!$A$5,'Common Size_IS'!F$1)} -> 0.058804086 | G13: {=INDEX('Income Statement'!$A$1:$H$27,'Common Size_IS'!$A13,'Common Size_IS'!G$1)/INDEX('Income Statement'!$A$1:$H$27,'Common Size_IS'!$A$5,'Common Size_IS'!G$1)} -> 0.065535926 | H13: {=INDEX('Income Statement'!$A$1:$H$27,'Common Size_IS'!$A13,'Common Size_IS'!H$1)/INDEX('Income Statement'!$A$1:$H$27,'Common Size_IS'!$A$5,'Common Size_IS'!H$1)} -> 0.076601755
A14: =MATCH($B14,'Income Statement'!$B:$B,0) -> 14 | B14: Other Expenses | C14: {=INDEX('Income Statement'!$A$1:$H$27,'Common Size_IS'!$A14,'Common Size_IS'!C$1)/INDEX('Income Statement'!$A$1:$H$27,'Common Size_IS'!$A$5,'Common Size_IS'!C$1)} -> 0.16327194 | D14: {=INDEX('Income Statement'!$A$1:$H$27,'Common Size_IS'!$A14,'Common Size_IS'!D$1)/INDEX('Income Statement'!$A$1:$H$27,'Common Size_IS'!$A$5,'Common Size_IS'!D$1)} -> 0.1482633 | E14: {=INDEX('Income Statement'!$A$1:$H$27,'Common Size_IS'!$A14,'Common Size_IS'!E$1)/INDEX('Income Statement'!$A$1:$H$27,'Common Size_IS'!$A$5,'Common Size_IS'!E$1)} -> 0.14467577 | F14: {=INDEX('Income Statement'!$A$1:$H$27,'Common Size_IS'!$A14,'Common Size_IS'!F$1)/INDEX('Income Statement'!$A$1:$H$27,'Common Size_IS'!$A$5,'Common Size_IS'!F$1)} -> 0.14625649 | G14: {=INDEX('Income Statement'!$A$1:$H$27,'Common Size_IS'!$A14,'Common Size_IS'!G$1)/INDEX('Income Statement'!$A$1:$H$27,'Common Size_IS'!$A$5,'Common Size_IS'!G$1)} -> 0.15476551 | H14: {=INDEX('Income Statement'!$A$1:$H$27,'Common Size_IS'!$A14,'Common Size_IS'!H$1)/INDEX('Income Statement'!$A$1:$H$27,'Common Size_IS'!$A$5,'Common Size_IS'!H$1)} -> 0.17066197
A15: =MATCH($B15,'Income Statement'!$B:$B,0) -> 15 | B15: Total Expenses | C15: {=INDEX('Income Statement'!$A$1:$H$27,'Common Size_IS'!$A15,'Common Size_IS'!C$1)/INDEX('Income Statement'!$A$1:$H$27,'Common Size_IS'!$A$5,'Common Size_IS'!C$1)} -> 0.79408646 | D15: {=INDEX('Income Statement'!$A$1:$H$27,'Common Size_IS'!$A15,'Common Size_IS'!D$1)/INDEX('Income Statement'!$A$1:$H$27,'Common Size_IS'!$A$5,'Common Size_IS'!D$1)} -> 0.77637144 | E15: {=INDEX('Income Statement'!$A$1:$H$27,'Common Size_IS'!$A15,'Common Size_IS'!E$1)/INDEX('Income Statement'!$A$1:$H$27,'Common Size_IS'!$A$5,'Common Size_IS'!E$1)} -> 0.83493475 | F15: {=INDEX('Income Statement'!$A$1:$H$27,'Common Size_IS'!$A15,'Common Size_IS'!F$1)/INDEX('Income Statement'!$A$1:$H$27,'Common Size_IS'!$A$5,'Common Size_IS'!F$1)} -> 0.81849533 | G15: {=INDEX('Income Statement'!$A$1:$H$27,'Common Size_IS'!$A15,'Common Size_IS'!G$1)/INDEX('Income Statement'!$A$1:$H$27,'Common Size_IS'!$A$5,'Common Size_IS'!G$1)} -> 0.78630687 | H15: {=INDEX('Income Statement'!$A$1:$H$27,'Common Size_IS'!$A15,'Common Size_IS'!H$1)/INDEX('Income Statement'!$A$1:$H$27,'Common Size_IS'!$A$5,'Common Size_IS'!H$1)} -> 0.82285503
A17: =MATCH($B17,'Income Statement'!$B:$B,0) -> 17 | B17: EBITDA | C17: {=INDEX('Income Statement'!$A$1:$H$27,'Common Size_IS'!$A17,'Common Size_IS'!C$1)/INDEX('Income Statement'!$A$1:$H$27,'Common Size_IS'!$A$5,'Common Size_IS'!C$1)} -> 0.22097 | D17: {=INDEX('Income Statement'!$A$1:$H$27,'Common Size_IS'!$A17,'Common Size_IS'!D$1)/INDEX('Income Statement'!$A$1:$H$27,'Common Size_IS'!$A$5,'Common Size_IS'!D$1)} -> 0.23758577 | E17: {=INDEX('Income Statement'!$A$1:$H$27,'Common Size_IS'!$A17,'Common Size_IS'!E$1)/INDEX('Income Statement'!$A$1:$H$27,'Common Size_IS'!$A$5,'Common Size_IS'!E$1)} -> 0.17812344 | F17: {=INDEX('Income Statement'!$A$1:$H$27,'Common Size_IS'!$A17,'Common Size_IS'!F$1)/INDEX('Income Statement'!$A$1:$H$27,'Common Size_IS'!$A$5,'Common Size_IS'!F$1)} -> 0.19271069 | G17: {=INDEX('Income Statement'!$A$1:$H$27,'Common Size_IS'!$A17,'Common Size_IS'!G$1)/INDEX('Income Statement'!$A$1:$H$27,'Common Size_IS'!$A$5,'Common Size_IS'!G$1)} -> 0.23307516 | H17: {=INDEX('Income Statement'!$A$1:$H$27,'Common Size_IS'!$A17,'Common Size_IS'!H$1)/INDEX('Income Statement'!$A$1:$H$27,'Common Size_IS'!$A$5,'Common Size_IS'!H$1)} -> 0.19403332
A18: =MATCH($B18,'Income Statement'!$B:$B,0) -> 18 | B18: Depreciation and Amortisation Expense | C18: {=INDEX('Income Statement'!$A$1:$H$27,'Common Size_IS'!$A18,'Common Size_IS'!C$1)/INDEX('Income Statement'!$A$1:$H$27,'Common Size_IS'!$A$5,'Common Size_IS'!C$1)} -> 0.038617107 | D18: {=INDEX('Income Statement'!$A$1:$H$27,'Common Size_IS'!$A18,'Common Size_IS'!D$1)/INDEX('Income Statement'!$A$1:$H$27,'Common Size_IS'!$A$5,'Common Size_IS'!D$1)} -> 0.036442576 | E18: {=INDEX('Income Statement'!$A$1:$H$27,'Common Size_IS'!$A18,'Common Size_IS'!E$1)/INDEX('Income Statement'!$A$1:$H$27,'Common Size_IS'!$A$5,'Common Size_IS'!E$1)} -> 0.028052374 | F18: {=INDEX('Income Statement'!$A$1:$H$27,'Common Size_IS'!$A18,'Common Size_IS'!F$1)/INDEX('Income Statement'!$A$1:$H$27,'Common Size_IS'!$A$5,'Common Size_IS'!F$1)} -> 0.024878373 | G18: {=INDEX('Income Statement'!$A$1:$H$27,'Common Size_IS'!$A18,'Common Size_IS'!G$1)/INDEX('Income Statement'!$A$1:$H$27,'Common Size_IS'!$A$5,'Common Size_IS'!G$1)} -> 0.024031737 | H18: {=INDEX('Income Statement'!$A$1:$H$27,'Common Size_IS'!$A18,'Common Size_IS'!H$1)/INDEX('Income Statement'!$A$1:$H$27,'Common Size_IS'!$A$5,'Common Size_IS'!H$1)} -> 0.030270498
... A20: =MATCH($B20,'Income Statement'!$B:$B,0) -> 20 | B20: Finance Costs | C20: {=INDEX('Income Statement'!$A$1:$H$27,'Common Size_IS'!$A20,'Common Size_IS'!C$1)/INDEX('Income Statement'!$A$1:$H$27,'Common Size_IS'!$A$5,'Common Size_IS'!C$1)} -> 0.0050630218 | D20: {=INDEX('Income Statement'!$A$1:$H$27,'Common Size_IS'!$A20,'Common Size_IS'!D$1)/INDEX('Income Statement'!$A$1:$H$27,'Common Size_IS'!$A$5,'Common Size_IS'!D$1)} -> 0.0042200933 | E20: {=INDEX('Income Statement'!$A$1:$H$27,'Common Size_IS'!$A20,'Common Size_IS'!E$1)/INDEX('Income Statement'!$A$1:$H$27,'Common Size_IS'!$A$5,'Common Size_IS'!E$1)} -> 0.0032785499 | F20: {=INDEX('Income Statement'!$A$1:$H$27,'Common Size_IS'!$A20,'Common Size_IS'!F$1)/INDEX('Income Statement'!$A$1:$H$27,'Common Size_IS'!$A$5,'Common Size_IS'!F$1)} -> 0.0041883417 | G20: {=INDEX('Income Statement'!$A$1:$H$27,'Common Size_IS'!$A20,'Common Size_IS'!G$1)/INDEX('Income Statement'!$A$1:$H$27,'Common Size_IS'!$A$5,'Common Size_IS'!G$1)} -> 0.0057802947 | H20: {=INDEX('Income Statement'!$A$1:$H$27,'Common Size_IS'!$A20,'Common Size_IS'!H$1)/INDEX('Income Statement'!$A$1:$H$27,'Common Size_IS'!$A$5,'Common Size_IS'!H$1)} -> 0.0066956451
A21: =MATCH($B21,'Income Statement'!$B:$B,0) -> 21 | B21: =PROPER("PROFIT BEFORE SHARE OF PROFIT IN ASSOCIATES AND EXCEPTIONAL ITEMS") -> Profit Before Share Of Profit In Associates And Exceptional Items | C21: {=INDEX('Income Statement'!$A$1:$H$27,'Common Size_IS'!$A21,'Common Size_IS'!C$1)/INDEX('Income Statement'!$A$1:$H$27,'Common Size_IS'!$A$5,'Common Size_IS'!C$1)} -> 0.17728988 | D21: {=INDEX('Income Statement'!$A$1:$H$27,'Common Size_IS'!$A21,'Common Size_IS'!D$1)/INDEX('Income Statement'!$A$1:$H$27,'Common Size_IS'!$A$5,'Common Size_IS'!D$1)} -> 0.1969231 | E21: {=INDEX('Income Statement'!$A$1:$H$27,'Common Size_IS'!$A21,'Common Size_IS'!E$1)/INDEX('Income Statement'!$A$1:$H$27,'Common Size_IS'!$A$5,'Common Size_IS'!E$1)} -> 0.14679251 | F21: {=INDEX('Income Statement'!$A$1:$H$27,'Common Size_IS'!$A21,'Common Size_IS'!F$1)/INDEX('Income Statement'!$A$1:$H$27,'Common Size_IS'!$A$5,'Common Size_IS'!F$1)} -> 0.16364398 | G21: {=INDEX('Income Statement'!$A$1:$H$27,'Common Size_IS'!$A21,'Common Size_IS'!G$1)/INDEX('Income Statement'!$A$1:$H$27,'Common Size_IS'!$A$5,'Common Size_IS'!G$1)} -> 0.20326313 | H21: {=INDEX('Income Statement'!$A$1:$H$27,'Common Size_IS'!$A21,'Common Size_IS'!H$1)/INDEX('Income Statement'!$A$1:$H$27,'Common Size_IS'!$A$5,'Common Size_IS'!H$1)} -> 0.15706718
A22: =MATCH($B22,'Income Statement'!$B:$B,0) -> 22 | B22: Share of profit in Associates | C22: {=INDEX('Income Statement'!$A$1:$H$27,'Common Size_IS'!$A22,'Common Size_IS'!C$1)/INDEX('Income Statement'!$A$1:$H$27,'Common Size_IS'!$A$5,'Common Size_IS'!C$1)} -> 0.002510483 | D22: {=INDEX('Income Statement'!$A$1:$H$27,'Common Size_IS'!$A22,'Common Size_IS'!D$1)/INDEX('Income Statement'!$A$1:$H$27,'Common Size_IS'!$A$5,'Common Size_IS'!D$1)} -> 0.001317196 | E22: {=INDEX('Income Statement'!$A$1:$H$27,'Common Size_IS'!$A22,'Common Size_IS'!E$1)/INDEX('Income Statement'!$A$1:$H$27,'Common Size_IS'!$A$5,'Common Size_IS'!E$1)} -> 0.001084832 | F22: {=INDEX('Income Statement'!$A$1:$H$27,'Common Size_IS'!$A22,'Common Size_IS'!F$1)/INDEX('Income Statement'!$A$1:$H$27,'Common Size_IS'!$A$5,'Common Size_IS'!F$1)} -> 0.0027211898 | G22: {=INDEX('Income Statement'!$A$1:$H$27,'Common Size_IS'!$A22,'Common Size_IS'!G$1)/INDEX('Income Statement'!$A$1:$H$27,'Common Size_IS'!$A$5,'Common Size_IS'!G$1)} -> 0.0037470351 | H22: {=INDEX('Income Statement'!$A$1:$H$27,'Common Size_IS'!$A22,'Common Size_IS'!H$1)/INDEX('Income Statement'!$A$1:$H$27,'Common Size_IS'!$A$5,'Common Size_IS'!H$1)} -> 0.0041500495
A23: =MATCH($B23,'Income Statement'!$B:$B,0) -> 23 | B23: Profit Before Exceptional Items And Tax | C23: {=INDEX('Income Statement'!$A$1:$H$27,'Common Size_IS'!$A23,'Common Size_IS'!C$1)/INDEX('Income Statement'!$A$1:$H$27,'Common Size_IS'!$A$5,'Common Size_IS'!C$1)} -> 0.17980036 | D23: {=INDEX('Income Statement'!$A$1:$H$27,'Common Size_IS'!$A23,'Common Size_IS'!D$1)/INDEX('Income Statement'!$A$1:$H$27,'Common Size_IS'!$A$5,'Common Size_IS'!D$1)} -> 0.1982403 | E23: {=INDEX('Income Statement'!$A$1:$H$27,'Common Size_IS'!$A23,'Common Size_IS'!E$1)/INDEX('Income Statement'!$A$1:$H$27,'Common Size_IS'!$A$5,'Common Size_IS'!E$1)} -> 0.14787734 | F23: {=INDEX('Income Statement'!$A$1:$H$27,'Common Size_IS'!$A23,'Common Size_IS'!F$1)/INDEX('Income Statement'!$A$1:$H$27,'Common Size_IS'!$A$5,'Common Size_IS'!F$1)} -> 0.16636517 | G23: {=INDEX('Income Statement'!$A$1:$H$27,'Common Size_IS'!$A23,'Common Size_IS'!G$1)/INDEX('Income Statement'!$A$1:$H$27,'Common Size_IS'!$A$5,'Common Size_IS'!G$1)} -> 0.20701017 | H23: {=INDEX('Income Statement'!$A$1:$H$27,'Common Size_IS'!$A23,'Common Size_IS'!H$1)/INDEX('Income Statement'!$A$1:$H$27,'Common Size_IS'!$A$5,'Common Size_IS'!H$1)} -> 0.16121723
A24: =MATCH($B24,'Income Statement'!$B:$B,0) -> 24 | B24: Exceptional Items | C24: {=INDEX('Income Statement'!$A$1:$H$27,'Common Size_IS'!$A24,'Common Size_IS'!C$1)/INDEX('Income Statement'!$A$1:$H$27,'Common Size_IS'!$A$5,'Common Size_IS'!C$1)} -> 0 | D24: {=INDEX('Income Statement'!$A$1:$H$27,'Common Size_IS'!$A24,'Common Size_IS'!D$1)/INDEX('Income Statement'!$A$1:$H$27,'Common Size_IS'!$A$5,'Common Size_IS'!D$1)} -> 0 | E24: {=INDEX('Income Statement'!$A$1:$H$27,'Common Size_IS'!$A24,'Common Size_IS'!E$1)/INDEX('Income Statement'!$A$1:$H$27,'Common Size_IS'!$A$5,'Common Size_IS'!E$1)} -> 0.0039757701 | F24: {=INDEX('Income Statement'!$A$1:$H$27,'Common Size_IS'!$A24,'Common Size_IS'!F$1)/INDEX('Income Statement'!$A$1:$H$27,'Common Size_IS'!$A$5,'Common Size_IS'!F$1)} -> 0.0014169904 | G24: {=INDEX('Income Statement'!$A$1:$H$27,'Common Size_IS'!$A24,'Common Size_IS'!G$1)/INDEX('Income Statement'!$A$1:$H$27,'Common Size_IS'!$A$5,'Common Size_IS'!G$1)} -> 0 | H24: {=INDEX('Income Statement'!$A$1:$H$27,'Common Size_IS'!$A24,'Common Size_IS'!H$1)/INDEX('Income Statement'!$A$1:$H$27,'Common Size_IS'!$A$5,'Common Size_IS'!H$1)} -> 0.010709139
A25: =MATCH($B25,'Income Statement'!$B:$B,0) -> 25 | B25: EBT | C25: {=INDEX('Income Statement'!$A$1:$H$27,'Common Size_IS'!$A25,'Common Size_IS'!C$1)/INDEX('Income Statement'!$A$1:$H$27,'Common Size_IS'!$A$5,'Common Size_IS'!C$1)} -> 0.17980036 | D25: {=INDEX('Income Statement'!$A$1:$H$27,'Common Size_IS'!$A25,'Common Size_IS'!D$1)/INDEX('Income Statement'!$A$1:$H$27,'Common Size_IS'!$A$5,'Common Size_IS'!D$1)} -> 0.1982403 | E25: {=INDEX('Income Statement'!$A$1:$H$27,'Common Size_IS'!$A25,'Common Size_IS'!E$1)/INDEX('Income Statement'!$A$1:$H$27,'Common Size_IS'!$A$5,'Common Size_IS'!E$1)} -> 0.14390157 | F25: {=INDEX('Income Statement'!$A$1:$H$27,'Common Size_IS'!$A25,'Common Size_IS'!F$1)/INDEX('Income Statement'!$A$1:$H$27,'Common Size_IS'!$A$5,'Common Size_IS'!F$1)} -> 0.16494818 | G25: {=INDEX('Income Statement'!$A$1:$H$27,'Common Size_IS'!$A25,'Common Size_IS'!G$1)/INDEX('Income Statement'!$A$1:$H$27,'Common Size_IS'!$A$5,'Common Size_IS'!G$1)} -> 0.20701017 | H25: {=INDEX('Income Statement'!$A$1:$H$27,'Common Size_IS'!$A25,'Common Size_IS'!H$1)/INDEX('Income Statement'!$A$1:$H$27,'Common Size_IS'!$A$5,'Common Size_IS'!H$1)} -> 0.15050809
A26: =MATCH($B26,'Income Statement'!$B:$B,0) -> 26 | B26: Tax expense | C26: {=INDEX('Income Statement'!$A$1:$H$27,'Common Size_IS'!$A26,'Common Size_IS'!C$1)/INDEX('Income Statement'!$A$1:$H$27,'Common Size_IS'!$A$5,'Common Size_IS'!C$1)} -> 0.042295751 | D26: {=INDEX('Income Statement'!$A$1:$H$27,'Common Size_IS'!$A26,'Common Size_IS'!D$1)/INDEX('Income Statement'!$A$1:$H$27,'Common Size_IS'!$A$5,'Common Size_IS'!D$1)} -> 0.05055085 | E26: {=INDEX('Income Statement'!$A$1:$H$27,'Common Size_IS'!$A26,'Common Size_IS'!E$1)/INDEX('Income Statement'!$A$1:$H$27,'Common Size_IS'!$A$5,'Common Size_IS'!E$1)} -> 0.03789902 | F26: {=INDEX('Income Statement'!$A$1:$H$27,'Common Size_IS'!$A26,'Common Size_IS'!F$1)/INDEX('Income Statement'!$A$1:$H$27,'Common Size_IS'!$A$5,'Common Size_IS'!F$1)} -> 0.043304177 | G26: {=INDEX('Income Statement'!$A$1:$H$27,'Common Size_IS'!$A26,'Common Size_IS'!G$1)/INDEX('Income Statement'!$A$1:$H$27,'Common Size_IS'!$A$5,'Common Size_IS'!G$1)} -> 0.050432275 | H26: {=INDEX('Income Statement'!$A$1:$H$27,'Common Size_IS'!$A26,'Common Size_IS'!H$1)/INDEX('Income Statement'!$A$1:$H$27,'Common Size_IS'!$A$5,'Common Size_IS'!H$1)} -> 0.041095252
A27: =MATCH($B27,'Income Statement'!$B:$B,0) -> 27 | B27: PAT | C27: {=INDEX('Income Statement'!$A$1:$H$27,'Common Size_IS'!$A27,'Common Size_IS'!C$1)/INDEX('Income Statement'!$A$1:$H$27,'Common Size_IS'!$A$5,'Common Size_IS'!C$1)} -> 0.13750461 | D27: {=INDEX('Income Statement'!$A$1:$H$27,'Common Size_IS'!$A27,'Common Size_IS'!D$1)/INDEX('Income Statement'!$A$1:$H$27,'Common Size_IS'!$A$5,'Common Size_IS'!D$1)} -> 0.14768945 | E27: {=INDEX('Income Statement'!$A$1:$H$27,'Common Size_IS'!$A27,'Common Size_IS'!E$1)/INDEX('Income Statement'!$A$1:$H$27,'Common Size_IS'!$A$5,'Common Size_IS'!E$1)} -> 0.10600255 | F27: {=INDEX('Income Statement'!$A$1:$H$27,'Common Size_IS'!$A27,'Common Size_IS'!F$1)/INDEX('Income Statement'!$A$1:$H$27,'Common Size_IS'!$A$5,'Common Size_IS'!F$1)} -> 0.121644 | G27: {=INDEX('Income Statement'!$A$1:$H$27,'Common Size_IS'!$A27,'Common Size_IS'!G$1)/INDEX('Income Statement'!$A$1:$H$27,'Common Size_IS'!$A$5,'Common Size_IS'!G$1)} -> 0.15657789 | H27: {=INDEX('Income Statement'!$A$1:$H$27,'Common Size_IS'!$A27,'Common Size_IS'!H$1)/INDEX('Income Statement'!$A$1:$H$27,'Common Size_IS'!$A$5,'Common Size_IS'!H$1)} -> 0.10941283

Sheet Common_Size_BS
C1: =MATCH(C4,'Balance Sheet'!4:4,0) -> 3 | D1: =MATCH(D4,'Balance Sheet'!4:4,0) -> 4 | E1: =MATCH(E4,'Balance Sheet'!4:4,0) -> 5 | F1: =MATCH(F4,'Balance Sheet'!4:4,0) -> 6 | G1: =MATCH(G4,'Balance Sheet'!4:4,0) -> 7 | H1: =MATCH(H4,'Balance Sheet'!4:4,0) -> 8
A2: Common-Size balance Sheet (with Total Assets as base)
B4: Particulars | C4: ='Income Statement'!C4 -> 2020 | D4: ='Income Statement'!D4 -> 2021 | E4: ='Income Statement'!E4 -> 2022 | F4: ='Income Statement'!F4 -> 2023 | G4: ='Income Statement'!G4 -> 2024 | H4: ='Income Statement'!H4 -> 2025
B5: Equity & Liabilities
B6: Equity
A7: =MATCH(B7,'Balance Sheet'!B:B,) -> 7 | B7: Equity Share Capital | C7: {=INDEX('Balance Sheet'!$A$1:$H$35,Common_Size_BS!$A7,Common_Size_BS!C$1)/INDEX('Balance Sheet'!$A$1:$H$35,Common_Size_BS!$A$35,Common_Size_BS!C$1)} -> 0.0059375652 | D7: {=INDEX('Balance Sheet'!$A$1:$H$35,Common_Size_BS!$A7,Common_Size_BS!D$1)/INDEX('Balance Sheet'!$A$1:$H$35,Common_Size_BS!$A$35,Common_Size_BS!D$1)} -> 0.0047089735 | E7: {=INDEX('Balance Sheet'!$A$1:$H$35,Common_Size_BS!$A7,Common_Size_BS!E$1)/INDEX('Balance Sheet'!$A$1:$H$35,Common_Size_BS!$A$35,Common_Size_BS!E$1)} -> 0.0041732563 | F7: {=INDEX('Balance Sheet'!$A$1:$H$35,Common_Size_BS!$A7,Common_Size_BS!F$1)/INDEX('Balance Sheet'!$A$1:$H$35,Common_Size_BS!$A$35,Common_Size_BS!F$1)} -> 0.0037181177 | G7: {=INDEX('Balance Sheet'!$A$1:$H$35,Common_Size_BS!$A7,Common_Size_BS!G$1)/INDEX('Balance Sheet'!$A$1:$H$35,Common_Size_BS!$A$35,Common_Size_BS!G$1)} -> 0.0032054442 | H7: {=INDEX('Balance Sheet'!$A$1:$H$35,Common_Size_BS!$A7,Common_Size_BS!H$1)/INDEX('Balance Sheet'!$A$1:$H$35,Common_Size_BS!$A$35,Common_Size_BS!H$1)} -> 0.0031582375
A8: =MATCH(B8,'Balance Sheet'!B:B,) -> 8 | B8: Other Equity | C8: {=INDEX('Balance Sheet'!$A$1:$H$35,Common_Size_BS!$A8,Common_Size_BS!C$1)/INDEX('Balance Sheet'!$A$1:$H$35,Common_Size_BS!$A$35,Common_Size_BS!C$1)} -> 0.62113172 | D8: {=INDEX('Balance Sheet'!$A$1:$H$35,Common_Size_BS!$A8,Common_Size_BS!D$1)/INDEX('Balance Sheet'!$A$1:$H$35,Common_Size_BS!$A$35,Common_Size_BS!D$1)} -> 0.6239866 | E8: {=INDEX('Balance Sheet'!$A$1:$H$35,Common_Size_BS!$A8,Common_Size_BS!E$1)/INDEX('Balance Sheet'!$A$1:$H$35,Common_Size_BS!$A$35,Common_Size_BS!E$1)} -> 0.59673562 | F8: {=INDEX('Balance Sheet'!$A$1:$H$35,Common_Size_BS!$A8,Common_Size_BS!F$1)/INDEX('Balance Sheet'!$A$1:$H$35,Common_Size_BS!$A$35,Common_Size_BS!F$1)} -> 0.61618381 | G8: {=INDEX('Balance Sheet'!$A$1:$H$35,Common_Size_BS!$A8,Common_Size_BS!G$1)/INDEX('Balance Sheet'!$A$1:$H$35,Common_Size_BS!$A$35,Common_Size_BS!G$1)} -> 0.62265486 | H8: {=INDEX('Balance Sheet'!$A$1:$H$35,Common_Size_BS!$A8,Common_Size_BS!H$1)/INDEX('Balance Sheet'!$A$1:$H$35,Common_Size_BS!$A$35,Common_Size_BS!H$1)} -> 0.63559497
A9: =MATCH(B9,'Balance Sheet'!B:B,) -> 9 | B9: Equity attributable to owners | C9: {=INDEX('Balance Sheet'!$A$1:$H$35,Common_Size_BS!$A9,Common_Size_BS!C$1)/INDEX('Balance Sheet'!$A$1:$H$35,Common_Size_BS!$A$35,Common_Size_BS!C$1)} -> 0.62706928 | D9: {=INDEX('Balance Sheet'!$A$1:$H$35,Common_Size_BS!$A9,Common_Size_BS!D$1)/INDEX('Balance Sheet'!$A$1:$H$35,Common_Size_BS!$A$35,Common_Size_BS!D$1)} -> 0.62869558 | E9: {=INDEX('Balance Sheet'!$A$1:$H$35,Common_Size_BS!$A9,Common_Size_BS!E$1)/INDEX('Balance Sheet'!$A$1:$H$35,Common_Size_BS!$A$35,Common_Size_BS!E$1)} -> 0.60090888 | F9: {=INDEX('Balance Sheet'!$A$1:$H$35,Common_Size_BS!$A9,Common_Size_BS!F$1)/INDEX('Balance Sheet'!$A$1:$H$35,Common_Size_BS!$A$35,Common_Size_BS!F$1)} -> 0.61990193 | G9: {=INDEX('Balance Sheet'!$A$1:$H$35,Common_Size_BS!$A9,Common_Size_BS!G$1)/INDEX('Balance Sheet'!$A$1:$H$35,Common_Size_BS!$A$35,Common_Size_BS!G$1)} -> 0.6258603 | H9: {=INDEX('Balance Sheet'!$A$1:$H$35,Common_Size_BS!$A9,Common_Size_BS!H$1)/INDEX('Balance Sheet'!$A$1:$H$35,Common_Size_BS!$A$35,Common_Size_BS!H$1)} -> 0.63875321
A10: =MATCH(B10,'Balance Sheet'!B:B,) -> 10 | B10: Non-Controlling Interests | C10: {=INDEX('Balance Sheet'!$A$1:$H$35,Common_Size_BS!$A10,Common_Size_BS!C$1)/INDEX('Balance Sheet'!$A$1:$H$35,Common_Size_BS!$A$35,Common_Size_BS!C$1)} -> 0.024979 | D10: {=INDEX('Balance Sheet'!$A$1:$H$35,Common_Size_BS!$A10,Common_Size_BS!D$1)/INDEX('Balance Sheet'!$A$1:$H$35,Common_Size_BS!$A$35,Common_Size_BS!D$1)} -> 0.020759347 | E10: {=INDEX('Balance Sheet'!$A$1:$H$35,Common_Size_BS!$A10,Common_Size_BS!E$1)/INDEX('Balance Sheet'!$A$1:$H$35,Common_Size_BS!$A$35,Common_Size_BS!E$1)} -> 0.01686053 | F10: {=INDEX('Balance Sheet'!$A$1:$H$35,Common_Size_BS!$A10,Common_Size_BS!F$1)/INDEX('Balance Sheet'!$A$1:$H$35,Common_Size_BS!$A$35,Common_Size_BS!F$1)} -> 0.017585084 | G10: {=INDEX('Balance Sheet'!$A$1:$H$35,Common_Size_BS!$A10,Common_Size_BS!G$1)/INDEX('Balance Sheet'!$A$1:$H$35,Common_Size_BS!$A$35,Common_Size_BS!G$1)} -> 0.023238134 | H10: {=INDEX('Balance Sheet'!$A$1:$H$35,Common_Size_BS!$A10,Common_Size_BS!H$1)/INDEX('Balance Sheet'!$A$1:$H$35,Common_Size_BS!$A$35,Common_Size_BS!H$1)} -> 0.021705968
A11: =MATCH(B11,'Balance Sheet'!B:B,) -> 11 | B11: Total Equity | C11: {=INDEX('Balance Sheet'!$A$1:$H$35,Common_Size_BS!$A11,Common_Size_BS!C$1)/INDEX('Balance Sheet'!$A$1:$H$35,Common_Size_BS!$A$35,Common_Size_BS!C$1)} -> 0.65204828 | D11: {=INDEX('Balance Sheet'!$A$1:$H$35,Common_Size_BS!$A11,Common_Size_BS!D$1)/INDEX('Balance Sheet'!$A$1:$H$35,Common_Size_BS!$A$35,Common_Size_BS!D$1)} -> 0.64945492 | E11: {=INDEX('Balance Sheet'!$A$1:$H$35,Common_Size_BS!$A11,Common_Size_BS!E$1)/INDEX('Balance Sheet'!$A$1:$H$35,Common_Size_BS!$A$35,Common_Size_BS!E$1)} -> 0.6177694 | F11: {=INDEX('Balance Sheet'!$A$1:$H$35,Common_Size_BS!$A11,Common_Size_BS!F$1)/INDEX('Balance Sheet'!$A$1:$H$35,Common_Size_BS!$A$35,Common_Size_BS!F$1)} -> 0.63748701 | G11: {=INDEX('Balance Sheet'!$A$1:$H$35,Common_Size_BS!$A11,Common_Size_BS!G$1)/INDEX('Balance Sheet'!$A$1:$H$35,Common_Size_BS!$A$35,Common_Size_BS!G$1)} -> 0.64909844 | H11: {=INDEX('Balance Sheet'!$A$1:$H$35,Common_Size_BS!$A11,Common_Size_BS!H$1)/INDEX('Balance Sheet'!$A$1:$H$35,Common_Size_BS!$A$35,Common_Size_BS!H$1)} -> 0.66045918
B13: Liabilities
A14: =MATCH(B14,'Balance Sheet'!B:B,) -> 14 | B14: Non-Current Liabilities
A15: =MATCH(B15,'Balance Sheet'!B:B,) -> 15 | B15: Long Term Borrowings | C15: {=INDEX('Balance Sheet'!$A$1:$H$35,Common_Size_BS!$A15,Common_Size_BS!C$1)/INDEX('Balance Sheet'!$A$1:$H$35,Common_Size_BS!$A$35,Common_Size_BS!C$1)} -> 0.037671227 | D15: {=INDEX('Balance Sheet'!$A$1:$H$35,Common_Size_BS!$A15,Common_Size_BS!D$1)/INDEX('Balance Sheet'!$A$1:$H$35,Common_Size_BS!$A$35,Common_Size_BS!D$1)} -> 0.028272005 | E15: {=INDEX('Balance Sheet'!$A$1:$H$35,Common_Size_BS!$A15,Common_Size_BS!E$1)/INDEX('Balance Sheet'!$A$1:$H$35,Common_Size_BS!$A$35,Common_Size_BS!E$1)} -> 0.02797152 | F15: {=INDEX('Balance Sheet'!$A$1:$H$35,Common_Size_BS!$A15,Common_Size_BS!F$1)/INDEX('Balance Sheet'!$A$1:$H$35,Common_Size_BS!$A$35,Common_Size_BS!F$1)} -> 0.031207458 | G15: {=INDEX('Balance Sheet'!$A$1:$H$35,Common_Size_BS!$A15,Common_Size_BS!G$1)/INDEX('Balance Sheet'!$A$1:$H$35,Common_Size_BS!$A$35,Common_Size_BS!G$1)} -> 0.038419548 | H15: {=INDEX('Balance Sheet'!$A$1:$H$35,Common_Size_BS!$A15,Common_Size_BS!H$1)/INDEX('Balance Sheet'!$A$1:$H$35,Common_Size_BS!$A$35,Common_Size_BS!H$1)} -> 0.045533672
A16: =MATCH(B16,'Balance Sheet'!B:B,) -> 16 | B16: Other Non-Current Liabilities | C16: {=INDEX('Balance Sheet'!$A$1:$H$35,Common_Size_BS!$A16,Common_Size_BS!C$1)/INDEX('Balance Sheet'!$A$1:$H$35,Common_Size_BS!$A$35,Common_Size_BS!C$1)} -> 0.039129619 | D16: {=INDEX('Balance Sheet'!$A$1:$H$35,Common_Size_BS!$A16,Common_Size_BS!D$1)/INDEX('Balance Sheet'!$A$1:$H$35,Common_Size_BS!$A$35,Common_Size_BS!D$1)} -> 0.031356501 | E16: {=INDEX('Balance Sheet'!$A$1:$H$35,Common_Size_BS!$A16,Common_Size_BS!E$1)/INDEX('Balance Sheet'!$A$1:$H$35,Common_Size_BS!$A$35,Common_Size_BS!E$1)} -> 0.024862896 | F16: {=INDEX('Balance Sheet'!$A$1:$H$35,Common_Size_BS!$A16,Common_Size_BS!F$1)/INDEX('Balance Sheet'!$A$1:$H$35,Common_Size_BS!$A$35,Common_Size_BS!F$1)} -> 0.025238003 | G16: {=INDEX('Balance Sheet'!$A$1:$H$35,Common_Size_BS!$A16,Common_Size_BS!G$1)/INDEX('Balance Sheet'!$A$1:$H$35,Common_Size_BS!$A$35,Common_Size_BS!G$1)} -> 0.028397856 | H16: {=INDEX('Balance Sheet'!$A$1:$H$35,Common_Size_BS!$A16,Common_Size_BS!H$1)/INDEX('Balance Sheet'!$A$1:$H$35,Common_Size_BS!$A$35,Common_Size_BS!H$1)} -> 0.025951085
A17: =MATCH(B17,'Balance Sheet'!B:B,) -> 17 | B17: Total Non-Current Liabilities | C17: {=INDEX('Balance Sheet'!$A$1:$H$35,Common_Size_BS!$A17,Common_Size_BS!C$1)/INDEX('Balance Sheet'!$A$1:$H$35,Common_Size_BS!$A$35,Common_Size_BS!C$1)} -> 0.076800846 | D17: {=INDEX('Balance Sheet'!$A$1:$H$35,Common_Size_BS!$A17,Common_Size_BS!D$1)/INDEX('Balance Sheet'!$A$1:$H$35,Common_Size_BS!$A$35,Common_Size_BS!D$1)} -> 0.059628506 | E17: {=INDEX('Balance Sheet'!$A$1:$H$35,Common_Size_BS!$A17,Common_Size_BS!E$1)/INDEX('Balance Sheet'!$A$1:$H$35,Common_Size_BS!$A$35,Common_Size_BS!E$1)} -> 0.052834416 | F17: {=INDEX('Balance Sheet'!$A$1:$H$35,Common_Size_BS!$A17,Common_Size_BS!F$1)/INDEX('Balance Sheet'!$A$1:$H$35,Common_Size_BS!$A$35,Common_Size_BS!F$1)} -> 0.056445461 | G17: {=INDEX('Balance Sheet'!$A$1:$H$35,Common_Size_BS!$A17,Common_Size_BS!G$1)/INDEX('Balance Sheet'!$A$1:$H$35,Common_Size_BS!$A$35,Common_Size_BS!G$1)} -> 0.066817404 | H17: {=INDEX('Balance Sheet'!$A$1:$H$35,Common_Size_BS!$A17,Common_Size_BS!H$1)/INDEX('Balance Sheet'!$A$1:$H$35,Common_Size_BS!$A$35,Common_Size_BS!H$1)} -> 0.071484757
B19: Current Liabilities
A20: =MATCH(B20,'Balance Sheet'!B:B,) -> 20 | B20: Short Term Borrowings | C20: {=INDEX('Balance Sheet'!$A$1:$H$35,Common_Size_BS!$A20,Common_Size_BS!C$1)/INDEX('Balance Sheet'!$A$1:$H$35,Common_Size_BS!$A$35,Common_Size_BS!C$1)} -> 0.03066277 | D20: {=INDEX('Balance Sheet'!$A$1:$H$35,Common_Size_BS!$A20,Common_Size_BS!D$1)/INDEX('Balance Sheet'!$A$1:$H$35,Common_Size_BS!$A$35,Common_Size_BS!D$1)} -> 0.025392226 | E20: {=INDEX('Balance Sheet'!$A$1:$H$35,Common_Size_BS!$A20,Common_Size_BS!E$1)/INDEX('Balance Sheet'!$A$1:$H$35,Common_Size_BS!$A$35,Common_Size_BS!E$1)} -> 0.041069941 | F20: {=INDEX('Balance Sheet'!$A$1:$H$35,Common_Size_BS!$A20,Common_Size_BS!F$1)/INDEX('Balance Sheet'!$A$1:$H$35,Common_Size_BS!$A$35,Common_Size_BS!F$1)} -> 0.043706101 | G20: {=INDEX('Balance Sheet'!$A$1:$H$35,Common_Size_BS!$A20,Common_Size_BS!G$1)/INDEX('Balance Sheet'!$A$1:$H$35,Common_Size_BS!$A$35,Common_Size_BS!G$1)} -> 0.044269015 | H20: {=INDEX('Balance Sheet'!$A$1:$H$35,Common_Size_BS!$A20,Common_Size_BS!H$1)/INDEX('Balance Sheet'!$A$1:$H$35,Common_Size_BS!$A$35,Common_Size_BS!H$1)} -> 0.029875834
A21: =MATCH(B21,'Balance Sheet'!B:B,) -> 21 | B21: Trade Payables | C21: {=INDEX('Balance Sheet'!$A$1:$H$35,Common_Size_BS!$A21,Common_Size_BS!C$1)/INDEX('Balance Sheet'!$A$1:$H$35,Common_Size_BS!$A$35,Common_Size_BS!C$1)} -> 0.13225629 | D21: {=INDEX('Balance Sheet'!$A$1:$H$35,Common_Size_BS!$A21,Common_Size_BS!D$1)/INDEX('Balance Sheet'!$A$1:$H$35,Common_Size_BS!$A$35,Common_Size_BS!D$1)} -> 0.16587055 | E21: {=INDEX('Balance Sheet'!$A$1:$H$35,Common_Size_BS!$A21,Common_Size_BS!E$1)/INDEX('Balance Sheet'!$A$1:$H$35,Common_Size_BS!$A$35,Common_Size_BS!E$1)} -> 0.18117901 | F21: {=INDEX('Balance Sheet'!$A$1:$H$35,Common_Size_BS!$A21,Common_Size_BS!F$1)/INDEX('Balance Sheet'!$A$1:$H$35,Common_Size_BS!$A$35,Common_Size_BS!F$1)} -> 0.14091945 | G21: {=INDEX('Balance Sheet'!$A$1:$H$35,Common_Size_BS!$A21,Common_Size_BS!G$1)/INDEX('Balance Sheet'!$A$1:$H$35,Common_Size_BS!$A$35,Common_Size_BS!G$1)} -> 0.12803531 | H21: {=INDEX('Balance Sheet'!$A$1:$H$35,Common_Size_BS!$A21,Common_Size_BS!H$1)/INDEX('Balance Sheet'!$A$1:$H$35,Common_Size_BS!$A$35,Common_Size_BS!H$1)} -> 0.12669827
A22: =MATCH(B22,'Balance Sheet'!B:B,) -> 22 | B22: Other Current Liabilities | C22: {=INDEX('Balance Sheet'!$A$1:$H$35,Common_Size_BS!$A22,Common_Size_BS!C$1)/INDEX('Balance Sheet'!$A$1:$H$35,Common_Size_BS!$A$35,Common_Size_BS!C$1)} -> 0.10823181 | D22: {=INDEX('Balance Sheet'!$A$1:$H$35,Common_Size_BS!$A22,Common_Size_BS!D$1)/INDEX('Balance Sheet'!$A$1:$H$35,Common_Size_BS!$A$35,Common_Size_BS!D$1)} -> 0.099653798 | E22: {=INDEX('Balance Sheet'!$A$1:$H$35,Common_Size_BS!$A22,Common_Size_BS!E$1)/INDEX('Balance Sheet'!$A$1:$H$35,Common_Size_BS!$A$35,Common_Size_BS!E$1)} -> 0.10714722 | F22: {=INDEX('Balance Sheet'!$A$1:$H$35,Common_Size_BS!$A22,Common_Size_BS!F$1)/INDEX('Balance Sheet'!$A$1:$H$35,Common_Size_BS!$A$35,Common_Size_BS!F$1)} -> 0.12144197 | G22: {=INDEX('Balance Sheet'!$A$1:$H$35,Common_Size_BS!$A22,Common_Size_BS!G$1)/INDEX('Balance Sheet'!$A$1:$H$35,Common_Size_BS!$A$35,Common_Size_BS!G$1)} -> 0.11177984 | H22: {=INDEX('Balance Sheet'!$A$1:$H$35,Common_Size_BS!$A22,Common_Size_BS!H$1)/INDEX('Balance Sheet'!$A$1:$H$35,Common_Size_BS!$A$35,Common_Size_BS!H$1)} -> 0.11148196
A23: =MATCH(B23,'Balance Sheet'!B:B,) -> 23 | B23: Total Current Liabilities | C23: {=INDEX('Balance Sheet'!$A$1:$H$35,Common_Size_BS!$A23,Common_Size_BS!C$1)/INDEX('Balance Sheet'!$A$1:$H$35,Common_Size_BS!$A$35,Common_Size_BS!C$1)} -> 0.27115087 | D23: {=INDEX('Balance Sheet'!$A$1:$H$35,Common_Size_BS!$A23,Common_Size_BS!D$1)/INDEX('Balance Sheet'!$A$1:$H$35,Common_Size_BS!$A$35,Common_Size_BS!D$1)} -> 0.29091657 | E23: {=INDEX('Balance Sheet'!$A$1:$H$35,Common_Size_BS!$A23,Common_Size_BS!E$1)/INDEX('Balance Sheet'!$A$1:$H$35,Common_Size_BS!$A$35,Common_Size_BS!E$1)} -> 0.32939618 | F23: {=INDEX('Balance Sheet'!$A$1:$H$35,Common_Size_BS!$A23,Common_Size_BS!F$1)/INDEX('Balance Sheet'!$A$1:$H$35,Common_Size_BS!$A$35,Common_Size_BS!F$1)} -> 0.30606752 | G23: {=INDEX('Balance Sheet'!$A$1:$H$35,Common_Size_BS!$A23,Common_Size_BS!G$1)/INDEX('Balance Sheet'!$A$1:$H$35,Common_Size_BS!$A$35,Common_Size_BS!G$1)} -> 0.28408416 | H23: {=INDEX('Balance Sheet'!$A$1:$H$35,Common_Size_BS!$A23,Common_Size_BS!H$1)/INDEX('Balance Sheet'!$A$1:$H$35,Common_Size_BS!$A$35,Common_Size_BS!H$1)} -> 0.26805607
A24: =MATCH(B24,'Balance Sheet'!B:B,) -> 24 | B24: TOTAL EQUITIES & LIABILITIES | C24: {=INDEX('Balance Sheet'!$A$1:$H$35,Common_Size_BS!$A24,Common_Size_BS!C$1)/INDEX('Balance Sheet'!$A$1:$H$35,Common_Size_BS!$A$35,Common_Size_BS!C$1)} -> 1 | D24: {=INDEX('Balance Sheet'!$A$1:$H$35,Common_Size_BS!$A24,Common_Size_BS!D$1)/INDEX('Balance Sheet'!$A$1:$H$35,Common_Size_BS!$A$35,Common_Size_BS!D$1)} -> 1 | E24: {=INDEX('Balance Sheet'!$A$1:$H$35,Common_Size_BS!$A24,Common_Size_BS!E$1)/INDEX('Balance Sheet'!$A$1:$H$35,Common_Size_BS!$A$35,Common_Size_BS!E$1)} -> 1 | F24: {=INDEX('Balance Sheet'!$A$1:$H$35,Common_Size_BS!$A24,Common_Size_BS!F$1)/INDEX('Balance Sheet'!$A$1:$H$35,Common_Size_BS!$A$35,Common_Size_BS!F$1)} -> 1 | G24: {=INDEX('Balance Sheet'!$A$1:$H$35,Common_Size_BS!$A24,Common_Size_BS!G$1)/INDEX('Balance Sheet'!$A$1:$H$35,Common_Size_BS!$A$35,Common_Size_BS!G$1)} -> 1 | H24: {=INDEX('Balance Sheet'!$A$1:$H$35,Common_Size_BS!$A24,Common_Size_BS!H$1)/INDEX('Balance Sheet'!$A$1:$H$35,Common_Size_BS!$A$35,Common_Size_BS!H$1)} -> 1
A26: =MATCH(B26,'Balance Sheet'!B:B,) -> 26 | B26: Assets
A27: =MATCH(B27,'Balance Sheet'!B:B,) -> 27 | B27: Total Non-Current Assets | C27: {=INDEX('Balance Sheet'!$A$1:$H$35,Common_Size_BS!$A27,Common_Size_BS!C$1)/INDEX('Balance Sheet'!$A$1:$H$35,Common_Size_BS!$A$35,Common_Size_BS!C$1)} -> 0.53078193 | D27: {=INDEX('Balance Sheet'!$A$1:$H$35,Common_Size_BS!$A27,Common_Size_BS!D$1)/INDEX('Balance Sheet'!$A$1:$H$35,Common_Size_BS!$A$35,Common_Size_BS!D$1)} -> 0.40958152 | E27: {=INDEX('Balance Sheet'!$A$1:$H$35,Common_Size_BS!$A27,Common_Size_BS!E$1)/INDEX('Balance Sheet'!$A$1:$H$35,Common_Size_BS!$A$35,Common_Size_BS!E$1)} -> 0.34075734 | F27: {=INDEX('Balance Sheet'!$A$1:$H$35,Common_Size_BS!$A27,Common_Size_BS!F$1)/INDEX('Balance Sheet'!$A$1:$H$35,Common_Size_BS!$A$35,Common_Size_BS!F$1)} -> 0.35905264 | G27: {=INDEX('Balance Sheet'!$A$1:$H$35,Common_Size_BS!$A27,Common_Size_BS!G$1)/INDEX('Balance Sheet'!$A$1:$H$35,Common_Size_BS!$A$35,Common_Size_BS!G$1)} -> 0.41394843 | H27: {=INDEX('Balance Sheet'!$A$1:$H$35,Common_Size_BS!$A27,Common_Size_BS!H$1)/INDEX('Balance Sheet'!$A$1:$H$35,Common_Size_BS!$A$35,Common_Size_BS!H$1)} -> 0.44053627
B29: Current Assets
A30: =MATCH(B30,'Balance Sheet'!B:B,) -> 30 | B30: Inventories | C30: {=INDEX('Balance Sheet'!$A$1:$H$35,Common_Size_BS!$A30,Common_Size_BS!C$1)/INDEX('Balance Sheet'!$A$1:$H$35,Common_Size_BS!$A$35,Common_Size_BS!C$1)} -> 0.20983338 | D30: {=INDEX('Balance Sheet'!$A$1:$H$35,Common_Size_BS!$A30,Common_Size_BS!D$1)/INDEX('Balance Sheet'!$A$1:$H$35,Common_Size_BS!$A$35,Common_Size_BS!D$1)} -> 0.1864836 | E30: {=INDEX('Balance Sheet'!$A$1:$H$35,Common_Size_BS!$A30,Common_Size_BS!E$1)/INDEX('Balance Sheet'!$A$1:$H$35,Common_Size_BS!$A$35,Common_Size_BS!E$1)} -> 0.26770186 | F30: {=INDEX('Balance Sheet'!$A$1:$H$35,Common_Size_BS!$A30,Common_Size_BS!F$1)/INDEX('Balance Sheet'!$A$1:$H$35,Common_Size_BS!$A$35,Common_Size_BS!F$1)} -> 0.24074114 | G30: {=INDEX('Balance Sheet'!$A$1:$H$35,Common_Size_BS!$A30,Common_Size_BS!G$1)/INDEX('Balance Sheet'!$A$1:$H$35,Common_Size_BS!$A$35,Common_Size_BS!G$1)} -> 0.19794787 | H30: {=INDEX('Balance Sheet'!$A$1:$H$35,Common_Size_BS!$A30,Common_Size_BS!H$1)/INDEX('Balance Sheet'!$A$1:$H$35,Common_Size_BS!$A$35,Common_Size_BS!H$1)} -> 0.22123697
A31: =MATCH(B31,'Balance Sheet'!B:B,) -> 31 | B31: Trade Receivables | C31: {=INDEX('Balance Sheet'!$A$1:$H$35,Common_Size_BS!$A31,Common_Size_BS!C$1)/INDEX('Balance Sheet'!$A$1:$H$35,Common_Size_BS!$A$35,Common_Size_BS!C$1)} -> 0.11112631 | D31: {=INDEX('Balance Sheet'!$A$1:$H$35,Common_Size_BS!$A31,Common_Size_BS!D$1)/INDEX('Balance Sheet'!$A$1:$H$35,Common_Size_BS!$A$35,Common_Size_BS!D$1)} -> 0.1277476 | E31: {=INDEX('Balance Sheet'!$A$1:$H$35,Common_Size_BS!$A31,Common_Size_BS!E$1)/INDEX('Balance Sheet'!$A$1:$H$35,Common_Size_BS!$A$35,Common_Size_BS!E$1)} -> 0.16843736 | F31: {=INDEX('Balance Sheet'!$A$1:$H$35,Common_Size_BS!$A31,Common_Size_BS!F$1)/INDEX('Balance Sheet'!$A$1:$H$35,Common_Size_BS!$A$35,Common_Size_BS!F$1)} -> 0.17974029 | G31: {=INDEX('Balance Sheet'!$A$1:$H$35,Common_Size_BS!$A31,Common_Size_BS!G$1)/INDEX('Balance Sheet'!$A$1:$H$35,Common_Size_BS!$A$35,Common_Size_BS!G$1)} -> 0.16338174 | H31: {=INDEX('Balance Sheet'!$A$1:$H$35,Common_Size_BS!$A31,Common_Size_BS!H$1)/INDEX('Balance Sheet'!$A$1:$H$35,Common_Size_BS!$A$35,Common_Size_BS!H$1)} -> 0.14203014
A32: =MATCH(B32,'Balance Sheet'!B:B,) -> 32 | B32: Cash, Bank & Cash Equivalents | C32: {=INDEX('Balance Sheet'!$A$1:$H$35,Common_Size_BS!$A32,Common_Size_BS!C$1)/INDEX('Balance Sheet'!$A$1:$H$35,Common_Size_BS!$A$35,Common_Size_BS!C$1)} -> 0.048458133 | D32: {=INDEX('Balance Sheet'!$A$1:$H$35,Common_Size_BS!$A32,Common_Size_BS!D$1)/INDEX('Balance Sheet'!$A$1:$H$35,Common_Size_BS!$A$35,Common_Size_BS!D$1)} -> 0.029983377 | E32: {=INDEX('Balance Sheet'!$A$1:$H$35,Common_Size_BS!$A32,Common_Size_BS!E$1)/INDEX('Balance Sheet'!$A$1:$H$35,Common_Size_BS!$A$35,Common_Size_BS!E$1)} -> 0.037604989 | F32: {=INDEX('Balance Sheet'!$A$1:$H$35,Common_Size_BS!$A32,Common_Size_BS!F$1)/INDEX('Balance Sheet'!$A$1:$H$35,Common_Size_BS!$A$35,Common_Size_BS!F$1)} -> 0.032708737 | G32: {=INDEX('Balance Sheet'!$A$1:$H$35,Common_Size_BS!$A32,Common_Size_BS!G$1)/INDEX('Balance Sheet'!$A$1:$H$35,Common_Size_BS!$A$35,Common_Size_BS!G$1)} -> 0.036225329 | H32: {=INDEX('Balance Sheet'!$A$1:$H$35,Common_Size_BS!$A32,Common_Size_BS!H$1)/INDEX('Balance Sheet'!$A$1:$H$35,Common_Size_BS!$A$35,Common_Size_BS!H$1)} -> 0.025747274
A33: =MATCH(B33,'Balance Sheet'!B:B,) -> 33 | B33: Other Current Assets | C33: {=INDEX('Balance Sheet'!$A$1:$H$35,Common_Size_BS!$A33,Common_Size_BS!C$1)/INDEX('Balance Sheet'!$A$1:$H$35,Common_Size_BS!$A$35,Common_Size_BS!C$1)} -> 0.099800245 | D33: {=INDEX('Balance Sheet'!$A$1:$H$35,Common_Size_BS!$A33,Common_Size_BS!D$1)/INDEX('Balance Sheet'!$A$1:$H$35,Common_Size_BS!$A$35,Common_Size_BS!D$1)} -> 0.24620391 | E33: {=INDEX('Balance Sheet'!$A$1:$H$35,Common_Size_BS!$A33,Common_Size_BS!E$1)/INDEX('Balance Sheet'!$A$1:$H$35,Common_Size_BS!$A$35,Common_Size_BS!E$1)} -> 0.18549846 | F33: {=INDEX('Balance Sheet'!$A$1:$H$35,Common_Size_BS!$A33,Common_Size_BS!F$1)/INDEX('Balance Sheet'!$A$1:$H$35,Common_Size_BS!$A$35,Common_Size_BS!F$1)} -> 0.18775719 | G33: {=INDEX('Balance Sheet'!$A$1:$H$35,Common_Size_BS!$A33,Common_Size_BS!G$1)/INDEX('Balance Sheet'!$A$1:$H$35,Common_Size_BS!$A$35,Common_Size_BS!G$1)} -> 0.18849663 | H33: {=INDEX('Balance Sheet'!$A$1:$H$35,Common_Size_BS!$A33,Common_Size_BS!H$1)/INDEX('Balance Sheet'!$A$1:$H$35,Common_Size_BS!$A$35,Common_Size_BS!H$1)} -> 0.17044934
A34: =MATCH(B34,'Balance Sheet'!B:B,) -> 34 | B34: Total Current Assets | C34: {=INDEX('Balance Sheet'!$A$1:$H$35,Common_Size_BS!$A34,Common_Size_BS!C$1)/INDEX('Balance Sheet'!$A$1:$H$35,Common_Size_BS!$A$35,Common_Size_BS!C$1)} -> 0.46921807 | D34: {=INDEX('Balance Sheet'!$A$1:$H$35,Common_Size_BS!$A34,Common_Size_BS!D$1)/INDEX('Balance Sheet'!$A$1:$H$35,Common_Size_BS!$A$35,Common_Size_BS!D$1)} -> 0.59041848 | E34: {=INDEX('Balance Sheet'!$A$1:$H$35,Common_Size_BS!$A34,Common_Size_BS!E$1)/INDEX('Balance Sheet'!$A$1:$H$35,Common_Size_BS!$A$35,Common_Size_BS!E$1)} -> 0.65924266 | F34: {=INDEX('Balance Sheet'!$A$1:$H$35,Common_Size_BS!$A34,Common_Size_BS!F$1)/INDEX('Balance Sheet'!$A$1:$H$35,Common_Size_BS!$A$35,Common_Size_BS!F$1)} -> 0.64094736 | G34: {=INDEX('Balance Sheet'!$A$1:$H$35,Common_Size_BS!$A34,Common_Size_BS!G$1)/INDEX('Balance Sheet'!$A$1:$H$35,Common_Size_BS!$A$35,Common_Size_BS!G$1)} -> 0.58605157 | H34: {=INDEX('Balance Sheet'!$A$1:$H$35,Common_Size_BS!$A34,Common_Size_BS!H$1)/INDEX('Balance Sheet'!$A$1:$H$35,Common_Size_BS!$A$35,Common_Size_BS!H$1)} -> 0.55946373
A35: =MATCH(B35,'Balance Sheet'!B:B,) -> 35 | B35: TOTAL ASSETS | C35: {=INDEX('Balance Sheet'!$A$1:$H$35,Common_Size_BS!$A35,Common_Size_BS!C$1)/INDEX('Balance Sheet'!$A$1:$H$35,Common_Size_BS!$A$35,Common_Size_BS!C$1)} -> 1 | D35: {=INDEX('Balance Sheet'!$A$1:$H$35,Common_Size_BS!$A35,Common_Size_BS!D$1)/INDEX('Balance Sheet'!$A$1:$H$35,Common_Size_BS!$A$35,Common_Size_BS!D$1)} -> 1 | E35: {=INDEX('Balance Sheet'!$A$1:$H$35,Common_Size_BS!$A35,Common_Size_BS!E$1)/INDEX('Balance Sheet'!$A$1:$H$35,Common_Size_BS!$A$35,Common_Size_BS!E$1)} -> 1 | F35: {=INDEX('Balance Sheet'!$A$1:$H$35,Common_Size_BS!$A35,Common_Size_BS!F$1)/INDEX('Balance Sheet'!$A$1:$H$35,Common_Size_BS!$A$35,Common_Size_BS!F$1)} -> 1 | G35: {=INDEX('Balance Sheet'!$A$1:$H$35,Common_Size_BS!$A35,Common_Size_BS!G$1)/INDEX('Balance Sheet'!$A$1:$H$35,Common_Size_BS!$A$35,Common_Size_BS!G$1)} -> 1 | H35: {=INDEX('Balance Sheet'!$A$1:$H$35,Common_Size_BS!$A35,Common_Size_BS!H$1)/INDEX('Balance Sheet'!$A$1:$H$35,Common_Size_BS!$A$35,Common_Size_BS!H$1)} -> 1

Sheet Ratio_Analysis
A2: Ratio Analysis
B4: Profitability Ratios | C4: ='Income Statement'!C4 -> 2020 | D4: ='Income Statement'!D4 -> 2021 | E4: ='Income Statement'!E4 -> 2022 | F4: ='Income Statement'!F4 -> 2023 | G4: ='Income Statement'!G4 -> 2024 | H4: ='Income Statement'!H4 -> 2025
B5: Operating Profit Margin | C5: ='Income Statement'!C19/'Income Statement'!C$5 -> 0.1823529 | D5: ='Income Statement'!D19/'Income Statement'!D$5 -> 0.2011432 | E5: ='Income Statement'!E19/'Income Statement'!E$5 -> 0.15007106 | F5: ='Income Statement'!F19/'Income Statement'!F$5 -> 0.16783232 | G5: ='Income Statement'!G19/'Income Statement'!G$5 -> 0.20904343 | H5: ='Income Statement'!H19/'Income Statement'!H$5 -> 0.16376282
B6: Net Profit Margin | C6: ='Income Statement'!C27/'Income Statement'!C$5 -> 0.13750461 | D6: ='Income Statement'!D27/'Income Statement'!D$5 -> 0.14768945 | E6: ='Income Statement'!E27/'Income Statement'!E$5 -> 0.10600255 | F6: ='Income Statement'!F27/'Income Statement'!F$5 -> 0.121644 | G6: ='Income Statement'!G27/'Income Statement'!G$5 -> 0.15657789 | H6: ='Income Statement'!H27/'Income Statement'!H$5 -> 0.10941283
B7: Return on Assets (ROA) | C7: ='Income Statement'!C$27/'Balance Sheet'!C$35 -> 0.17203216 | D7: ='Income Statement'!D$27/'Balance Sheet'!D$35 -> 0.15742807 | E7: ='Income Statement'!E$27/'Balance Sheet'!E$35 -> 0.13421291 | F7: ='Income Statement'!F$27/'Balance Sheet'!F$35 -> 0.1626223 | G7: ='Income Statement'!G$27/'Balance Sheet'!G$35 -> 0.18572628 | H7: ='Income Statement'!H$27/'Balance Sheet'!H$35 -> 0.12214497
B8: Return on Equity (ROE) | C8: ='Income Statement'!C$27/'Balance Sheet'!C$11 -> 0.26383347 | D8: ='Income Statement'!D$27/'Balance Sheet'!D$11 -> 0.24240031 | E8: ='Income Statement'!E$27/'Balance Sheet'!E$11 -> 0.21725406 | F8: ='Income Statement'!F$27/'Balance Sheet'!F$11 -> 0.25509899 | G8: ='Income Statement'!G$27/'Balance Sheet'!G$11 -> 0.28612961 | H8: ='Income Statement'!H$27/'Balance Sheet'!H$11 -> 0.18493947
B10: Liquidity Ratios | C10: =C$4 -> 2020 | D10: =D$4 -> 2021 | E10: =E$4 -> 2022 | F10: =F$4 -> 2023 | G10: =G$4 -> 2024 | H10: =H$4 -> 2025
B11: Current Ratio | C11: ='Balance Sheet'!C34/'Balance Sheet'!C23 -> 1.7304686 | D11: ='Balance Sheet'!D34/'Balance Sheet'!D23 -> 2.0295113 | E11: ='Balance Sheet'!E34/'Balance Sheet'!E23 -> 2.0013671 | F11: ='Balance Sheet'!F34/'Balance Sheet'!F23 -> 2.0941371 | G11: ='Balance Sheet'!G34/'Balance Sheet'!G23 -> 2.0629505 | H11: ='Balance Sheet'!H34/'Balance Sheet'!H23 -> 2.0871146
B12: Quick Ratio | C12: =('Balance Sheet'!C34-'Balance Sheet'!C30)/'Balance Sheet'!C23 -> 0.9566065 | D12: =('Balance Sheet'!D34-'Balance Sheet'!D30)/'Balance Sheet'!D23 -> 1.3884904 | E12: =('Balance Sheet'!E34-'Balance Sheet'!E30)/'Balance Sheet'!E23 -> 1.1886622 | F12: =('Balance Sheet'!F34-'Balance Sheet'!F30)/'Balance Sheet'!F23 -> 1.3075749 | G12: =('Balance Sheet'!G34-'Balance Sheet'!G30)/'Balance Sheet'!G23 -> 1.3661575 | H12: =('Balance Sheet'!H34-'Balance Sheet'!H30)/'Balance Sheet'!H23 -> 1.2617762
B14: Solvency Ratios | C14: =C$4 -> 2020 | D14: =D$4 -> 2021 | E14: =E$4 -> 2022 | F14: =F$4 -> 2023 | G14: =G$4 -> 2024 | H14: =H$4 -> 2025
B15: Debt to Equity Ratio | C15: ='Balance Sheet'!C40/'Balance Sheet'!C11 -> 0.10479898 | D15: ='Balance Sheet'!D40/'Balance Sheet'!D11 -> 0.082629647 | E15: ='Balance Sheet'!E40/'Balance Sheet'!E11 -> 0.11175927 | F15: ='Balance Sheet'!F40/'Balance Sheet'!F11 -> 0.11751386 | G15: ='Balance Sheet'!G40/'Balance Sheet'!G11 -> 0.12738987 | H15: ='Balance Sheet'!H40/'Balance Sheet'!H11 -> 0.11417739
